<?xml version="1.0"?>
<sdf version='1.11'>
  <model name='bumperbot'>
    <link name='base_footprint'>
      <inertial>
        <pose>1.363708992612298e-12 8.3952941522525651e-13 0.072999771618593862 0 0 0</pose>
        <mass>0.82573792758530062</mass>
        <inertia>
          <ixx>0.022155198973077161</ixx>
          <ixy>0.0001659028313244918</ixy>
          <ixz>-0.00017350148233748999</ixz>
          <iyy>0.021204357031449881</iyy>
          <iyz>-7.2665357729989331e-05</iyz>
          <izz>0.02002287110912172</izz>
        </inertia>
      </inertial>
      <collision name='base_footprint_fixed_joint_lump__base_link_collision'>
        <pose>0 0 0.033000000000000002 0 0 0</pose>
        <geometry>
          <mesh>
            <scale>1 1 1</scale>
            <uri>package://mz_gz_description/models/bumperbot/meshes/base_link.STL</uri>
          </mesh>
        </geometry>
      </collision>
      <collision name='base_footprint_fixed_joint_lump__caster_front_link_collision_1'>
        <pose>0.047550000000000002 0 0.0055000000000000014 0 0 0</pose>
        <geometry>
          <sphere>
            <radius>0.0050000000000000001</radius>
          </sphere>
        </geometry>
        <surface>
          <contact>
            <ode>
              <kp>1000000</kp>
              <kd>100</kd>
              <max_vel>1</max_vel>
              <min_depth>0.001</min_depth>
            </ode>
          </contact>
          <friction>
            <ode>
              <mu>0.10000000000000001</mu>
              <mu2>0.10000000000000001</mu2>
            </ode>
          </friction>
        </surface>
      </collision>
      <collision name='base_footprint_fixed_joint_lump__caster_rear_link_collision_2'>
        <pose>-0.047550000000000002 0 0.0055000000000000014 0 0 0</pose>
        <geometry>
          <sphere>
            <radius>0.0050000000000000001</radius>
          </sphere>
        </geometry>
        <surface>
          <contact>
            <ode>
              <kp>1000000</kp>
              <kd>100</kd>
              <max_vel>1</max_vel>
              <min_depth>0.001</min_depth>
            </ode>
          </contact>
          <friction>
            <ode>
              <mu>0.10000000000000001</mu>
              <mu2>0.10000000000000001</mu2>
            </ode>
          </friction>
        </surface>
      </collision>
      <visual name='base_footprint_fixed_joint_lump__base_link_visual'>
        <pose>0 0 0.033000000000000002 0 0 0</pose>
        <geometry>
          <mesh>
            <scale>1 1 1</scale>
            <uri>package://mz_gz_description/models/bumperbot/meshes/base_link.STL</uri>
          </mesh>
        </geometry>
      </visual>
      <visual name='base_footprint_fixed_joint_lump__caster_front_link_visual_1'>
        <pose>0.047550000000000002 0 0.0055000000000000014 0 0 0</pose>
        <geometry>
          <mesh>
            <scale>1 1 1</scale>
            <uri>package://mz_gz_description/models/bumperbot/meshes/caster_front_link.STL</uri>
          </mesh>
        </geometry>
      </visual>
      <visual name='base_footprint_fixed_joint_lump__caster_rear_link_visual_2'>
        <pose>-0.047550000000000002 0 0.0055000000000000014 0 0 0</pose>
        <geometry>
          <mesh>
            <scale>1 1 1</scale>
            <uri>package://mz_gz_description/models/bumperbot/meshes/caster_rear_link.STL</uri>
          </mesh>
        </geometry>
      </visual>
    </link>
    <joint name='wheel_left_joint' type='revolute'>
      <pose relative_to='base_footprint'>0 0.070110184941864204 0.033000000000000002 0 0 0</pose>
      <parent>base_footprint</parent>
      <child>wheel_left_link</child>
      <axis>
        <xyz>0 1 0</xyz>
        <limit>
          <lower>-inf</lower>
          <upper>inf</upper>
        </limit>
        <dynamics>
          <spring_reference>0</spring_reference>
          <spring_stiffness>0</spring_stiffness>
        </dynamics>
      </axis>
    </joint>
    <link name='wheel_left_link'>
      <pose relative_to='wheel_left_joint'>0 0 0 0 0 0</pose>
      <inertial>
        <pose>0 0.014 0 0 0 0</pose>
        <mass>0.053008604321764401</mass>
        <inertia>
          <ixx>1.8792911368908999e-05</ixx>
          <ixy>3.3125639220458398e-10</ixy>
          <ixz>-1.14082001662767e-08</ixz>
          <iyy>3.1151073875907298e-05</iyy>
          <iyz>-3.6049924508219202e-10</iyz>
          <izz>1.8826688614684699e-05</izz>
        </inertia>
      </inertial>
      <collision name='wheel_left_link_collision'>
        <pose>0 0.014999999999999999 0 -1.5700000000000001 0 0</pose>
        <geometry>
          <sphere>
            <radius>0.033000000000000002</radius>
          </sphere>
        </geometry>
        <surface>
          <contact>
            <ode>
              <kp>1000000000000</kp>
              <kd>10</kd>
              <max_vel>0.10000000000000001</max_vel>
              <min_depth>0.001</min_depth>
            </ode>
          </contact>
          <friction>
            <ode>
              <mu>1000000000000000</mu>
              <mu2>1000000000000000</mu2>
              <fdir1>1 0 0</fdir1>
            </ode>
          </friction>
        </surface>
      </collision>
      <visual name='wheel_left_link_visual'>
        <pose>0 0 0 -1.5700000000000001 0 0</pose>
        <geometry>
          <mesh>
            <scale>1 1 1</scale>
            <uri>package://mz_gz_description/models/bumperbot/meshes/wheel_left_link.STL</uri>
          </mesh>
        </geometry>
      </visual>
    </link>
    <joint name='wheel_right_joint' type='revolute'>
      <pose relative_to='base_footprint'>0 -0.070110184941863704 0.033000000000000002 0 0 0</pose>
      <parent>base_footprint</parent>
      <child>wheel_right_link</child>
      <axis>
        <xyz>0 1 0</xyz>
        <limit>
          <lower>-inf</lower>
          <upper>inf</upper>
        </limit>
        <dynamics>
          <spring_reference>0</spring_reference>
          <spring_stiffness>0</spring_stiffness>
        </dynamics>
      </axis>
    </joint>
    <link name='wheel_right_link'>
      <pose relative_to='wheel_right_joint'>0 0 0 0 0 0</pose>
      <inertial>
        <pose>0 -0.014 0 0 0 0</pose>
        <mass>0.053008609096672099</mass>
        <inertia>
          <ixx>1.88176298336665e-05</ixx>
          <ixy>-4.8444933029986996e-10</ixy>
          <ixz>1.8816370885114301e-08</ixz>
          <iyy>3.1151073864776397e-05</iyy>
          <iyz>-6.93560663069607e-11</iyz>
          <izz>1.8801969558181999e-05</izz>
        </inertia>
      </inertial>
      <collision name='wheel_right_link_collision'>
        <pose>0 -0.014999999999999999 0 1.5700000000000001 0 0</pose>
        <geometry>
          <sphere>
            <radius>0.033000000000000002</radius>
          </sphere>
        </geometry>
        <surface>
          <contact>
            <ode>
              <kp>1000000000000</kp>
              <kd>10</kd>
              <max_vel>0.10000000000000001</max_vel>
              <min_depth>0.001</min_depth>
            </ode>
          </contact>
          <friction>
            <ode>
              <mu>1000000000000000</mu>
              <mu2>1000000000000000</mu2>
              <fdir1>1 0 0</fdir1>
            </ode>
          </friction>
        </surface>
      </collision>
      <visual name='wheel_right_link_visual'>
        <pose>0 0 0 1.5700000000000001 0 0</pose>
        <geometry>
          <mesh>
            <scale>1 1 1</scale>
            <uri>package://mz_gz_description/models/bumperbot/meshes/wheel_right_link.STL</uri>
          </mesh>
        </geometry>
      </visual>
    </link>

    <frame name='caster_front_joint' attached_to='base_link'>
      <pose>0.047550000000000002 0 -0.0275 0 0 0</pose>
    </frame>
    <frame name='caster_front_link' attached_to='caster_front_joint'>
      <pose>0 0 0 0 0 0</pose>
    </frame>
    <frame name='caster_rear_joint' attached_to='base_link'>
      <pose>-0.047550000000000002 0 -0.0275 0 0 0</pose>
    </frame>
    <frame name='caster_rear_link' attached_to='caster_rear_joint'>
      <pose>0 0 0 0 0 0</pose>
    </frame>
    <frame name='base_joint' attached_to='base_footprint'>
      <pose>0 0 0.033000000000000002 0 0 0</pose>
    </frame>
    <frame name='base_link' attached_to='base_joint'>
      <pose>0 0 0 0 0 0</pose>
    </frame>
  </model>
</sdf>
